<?xml version="1.0" ?>
<robot name="(Unsaved)" xmlns:xacro="http://www.ros.org/wiki/xacro">

<xacro:include filename="$(find (Unsaved)_description)/urdf/materials.xacro" />
<xacro:include filename="$(find (Unsaved)_description)/urdf/(Unsaved).trans" />
<xacro:include filename="$(find (Unsaved)_description)/urdf/(Unsaved).gazebo" />
<link name="base_link">
  <inertial>
    <origin xyz="6.0191304496625896e-15 0.003928280958519979 0.04802796973437256" rpy="0 0 0"/>
    <mass value="2.3128074428088716"/>
    <inertia ixx="0.008362" iyy="0.007904" izz="0.014762" ixy="0.0" iyz="-0.000341" ixz="0.0"/>
  </inertial>
  <visual>
    <origin xyz="0 0 0" rpy="0 0 0"/>
    <geometry>
      <mesh filename="package://(Unsaved)_description/meshes/base_link.stl" scale="0.001 0.001 0.001"/>
    </geometry>
    <material name="silver"/>
  </visual>
  <collision>
    <origin xyz="0 0 0" rpy="0 0 0"/>
    <geometry>
      <mesh filename="package://(Unsaved)_description/meshes/base_link.stl" scale="0.001 0.001 0.001"/>
    </geometry>
  </collision>
</link>

<link name="left_wheel_1">
  <inertial>
    <origin xyz="-0.010000000000000009 0.0 0.0" rpy="0 0 0"/>
    <mass value="0.11832808729745954"/>
    <inertia ixx="0.00012" iyy="6.4e-05" izz="6.4e-05" ixy="-0.0" iyz="-0.0" ixz="0.0"/>
  </inertial>
  <visual>
    <origin xyz="0.1 -0.0 -0.045" rpy="0 0 0"/>
    <geometry>
      <mesh filename="package://(Unsaved)_description/meshes/left_wheel_1.stl" scale="0.001 0.001 0.001"/>
    </geometry>
    <material name="silver"/>
  </visual>
  <collision>
    <origin xyz="0.1 -0.0 -0.045" rpy="0 0 0"/>
    <geometry>
      <mesh filename="package://(Unsaved)_description/meshes/left_wheel_1.stl" scale="0.001 0.001 0.001"/>
    </geometry>
  </collision>
</link>

<link name="right_wheel_1">
  <inertial>
    <origin xyz="0.009999999999999995 0.0 0.0" rpy="0 0 0"/>
    <mass value="0.11832808729745954"/>
    <inertia ixx="0.00012" iyy="6.4e-05" izz="6.4e-05" ixy="0.0" iyz="-0.0" ixz="0.0"/>
  </inertial>
  <visual>
    <origin xyz="-0.1 -0.0 -0.045" rpy="0 0 0"/>
    <geometry>
      <mesh filename="package://(Unsaved)_description/meshes/right_wheel_1.stl" scale="0.001 0.001 0.001"/>
    </geometry>
    <material name="silver"/>
  </visual>
  <collision>
    <origin xyz="-0.1 -0.0 -0.045" rpy="0 0 0"/>
    <geometry>
      <mesh filename="package://(Unsaved)_description/meshes/right_wheel_1.stl" scale="0.001 0.001 0.001"/>
    </geometry>
  </collision>
</link>

<link name="lidar_1">
  <inertial>
    <origin xyz="5.481179740805587e-18 0.0 0.012499999999999997" rpy="0 0 0"/>
    <mass value="0.8140963426821691"/>
    <inertia ixx="0.000311" iyy="0.000311" izz="0.000537" ixy="0.0" iyz="-0.0" ixz="-0.0"/>
  </inertial>
  <visual>
    <origin xyz="-0.0 -0.05 -0.105" rpy="0 0 0"/>
    <geometry>
      <mesh filename="package://(Unsaved)_description/meshes/lidar_1.stl" scale="0.001 0.001 0.001"/>
    </geometry>
    <material name="silver"/>
  </visual>
  <collision>
    <origin xyz="-0.0 -0.05 -0.105" rpy="0 0 0"/>
    <geometry>
      <mesh filename="package://(Unsaved)_description/meshes/lidar_1.stl" scale="0.001 0.001 0.001"/>
    </geometry>
  </collision>
</link>

<joint name="Rev1" type="continuous">
  <origin xyz="-0.1 0.0 0.045" rpy="0 0 0"/>
  <parent link="base_link"/>
  <child link="left_wheel_1"/>
  <axis xyz="-1.0 0.0 0.0"/>
</joint>

<joint name="Rev2" type="continuous">
  <origin xyz="0.1 0.0 0.045" rpy="0 0 0"/>
  <parent link="base_link"/>
  <child link="right_wheel_1"/>
  <axis xyz="1.0 0.0 0.0"/>
</joint>

<joint name="Rigid3" type="fixed">
  <origin xyz="0.0 0.05 0.105" rpy="0 0 0"/>
  <parent link="base_link"/>
  <child link="lidar_1"/>
</joint>

</robot>
